Workbook

Sheet Assumptions & Funding
A1: COGNITRONICS — ASSUMPTIONS & FUNDING
A2: Validated model conventions, financing terms and linked operating-cost baseline · 18-month pre-seed plan
A4: MODEL FRAME
A5: Model horizon | B5: 18 | C5: operating months : | D5: M1–M18 | E5: M0 is the financing event
A6: Model currency | B6: EUR (€) | C6: Reporting and cash-planning currency
A7: USD → EUR planning FX | B7: 0.93 | C7: $1 = €0.93
A8: Round target (USD) | B8: =SUM(C15:C17) -> 750000
A9: Funding envelope (EUR) | B9: =B8*B7 -> 697500
A10: Opening cash before first close | B10: 0 | C10: M0 before initial SAFE inflow
A11: Funding timing | B11: Scenario-driven | C11: Closing months will be editable in Runway & Scenarios
A13: SAFE ROUND TERMS
A14: Tier | B14: Order | C14: Allocation (USD) | D14: Allocation (EUR) | E14: Valuation Cap (USD) | F14: Instrument | G14: Terms | H14: Status
A15: Tier 1 | B15: 1 | C15: 200000 | D15: =C15*$B$7 -> 186000 | E15: 6000000 | F15: YC post-money SAFE | G15: Cap only · no discount · no MFN · no automatic pro-rata | H15: Validated
A16: Tier 2 | B16: 2 | C16: 250000 | D16: =C16*$B$7 -> 232500 | E16: 7500000 | F16: YC post-money SAFE | G16: Cap only · no discount · no MFN · no automatic pro-rata | H16: Validated
A17: Tier 3 | B17: 3 | C17: 300000 | D17: =C17*$B$7 -> 279000 | E17: 9000000 | F17: YC post-money SAFE | G17: Cap only · no discount · no MFN · no automatic pro-rata | H17: Validated
A18: TOTAL ROUND | C18: =SUM(C15:C17) -> 750000 | D18: =SUM(D15:D17) -> 697500 | F18: Standard SAFE at valuation cap | H18: LOCKED
A20: OPERATING & TAX CONVENTIONS
A21: Assumption | B21: Value | C21: Timing | D21: Classification | E21: Source / Note
A22: Operating plan length | B22: 18 | C22: M1–M18 | D22: Cash plan | E22: M0 is separate and represents the financing event.
A23: VAT recovery | B23: Conservative annual refund | C23: M13 for M1–M12 | D23: Working capital | E23: Apply only to invoice-level deductible VAT; M13–M18 recoverable VAT remains outstanding at plan end.
A24: CIR, grants and subsidies | B24: Excluded | C24: Base case | D24: No cash inflow | E24: Potential upside is not used to finance the base plan.
A25: HQ furniture, fit-out and appliances | B25: 5000 | C25: M1 | D25: CapEx | E25: Validated provision in HQ & lab est.
A26: Corporate liability, cyber and D&O insurance | B26: 4000 | C26: €2K M1 + €2K M13 | D26: OpEx | E26: Validated 18-month cash provision in Other expenses.
A27: Contingency policy | B27: Category-specific only | C27: Throughout | D27: Reserve | E27: Keep existing schedule-level contingencies; do not apply a second blanket contingency.
A28: Unallocated strategic reserve | B28: Funding less modeled expenditure | C28: M18 | D28: Liquidity | E28: Displayed separately and not treated as an operating expense.
A30: LINKED 18-MONTH COST BASE
A31: Schedule | B31: Total 12M | C31: Total 18M | D31: % of 18M spend | E31: Cost basis | F31: Source cell | G31: Status | H31: Notes
A32: Hiring & Compensation Plan | B32: ='Hiring & Compensation Plan'!W27 -> 207204.58 | C32: ='Hiring & Compensation Plan'!X27 -> 337743.58 | D32: =IF($C$36=0,0,C32/$C$36) -> 0.51677866 | E32: Employer cost | F32: Hiring & Compensation Plan!W27:X27 | G32: LINKED | H32: Includes fractional CTO
A33: MVP & lab hardware BOM | B33: ='MVP & lab hardware BOM'!V70 -> 61464.82 | C33: ='MVP & lab hardware BOM'!W70 -> 81897 | D33: =IF($C$36=0,0,C33/$C$36) -> 0.12530992 | E33: CapEx + technical OpEx | F33: MVP & lab hardware BOM!V70:W70 | G33: LINKED | H33: HT basis; VAT handled separately
A34: HQ & lab est. | B34: ='HQ & lab est.'!V31 -> 105365 | C34: ='HQ & lab est.'!W31 -> 148835 | D34: =IF($C$36=0,0,C34/$C$36) -> 0.22773121 | E34: Occupancy + hosting | F34: HQ & lab est.!V31:W31 | G34: LINKED | H34: Includes recoverable security deposit
A35: Other expenses | B35: ='Other expenses'!V35 -> 55100 | C35: ='Other expenses'!W35 -> 85080 | D35: =IF($C$36=0,0,C35/$C$36) -> 0.13018021 | E35: Strategic operations | F35: Other expenses!V35:W35 | G35: LINKED | H35: Includes annual corporate insurance
A36: TOTAL MODELED EXPENDITURE | B36: =SUM(B32:B35) -> 429134.4 | C36: =SUM(C32:C35) -> 653555.58 | D36: 1 | G36: RECONCILED
A37: FUNDING ENVELOPE | C37: =$B$9 -> 697500
A38: UNALLOCATED STRATEGIC RESERVE | C38: =C37-C36 -> 43944.42 | D38: =IF(C37=0,0,C38/C37) -> 0.063002753
A39: AVERAGE MONTHLY MODELED BURN | C39: =C36/$B$5 -> 36308.643
A41: MODEL CONTROLS
A42: Check | B42: Expected | C42: Actual | D42: Difference | E42: Status | F42: Notes
A43: SAFE allocations equal round target | B43: 750000 | C43: =$B$8 -> 750000 | D43: =C43-B43 -> 0 | E43: =IF(ABS(D43)<=1,"PASS","REVIEW") -> PASS | F43: Tier allocations must total $750K.
A44: EUR funding conversion | B44: 697500 | C44: =$B$9 -> 697500 | D44: =C44-B44 -> 0 | E44: =IF(ABS(D44)<=1,"PASS","REVIEW") -> PASS | F44: $750K × 0.93.
A45: SAFE tier count | B45: 3 | C45: =COUNTA(A15:A17) -> 3 | D45: =C45-B45 -> 0 | E45: =IF(D45=0,"PASS","REVIEW") -> PASS | F45: Three sequential pricing tiers.
...

Sheet Cap Table & Equity Plan
A1: COGNICS SYSTEMS, INC. — CAP TABLE & EQUITY PLAN
A2: Legal ownership, equity reserves, planned core-team grants and proposed SAFE dilution · investor diligence view
A3: Legal ownership, reserved equity, planned grants, and pro forma financing outcomes are shown separately. Core-team allocations and SAFE outcomes are illustrative planning assumptions only; they are not current legal ownership, executed grants, or issued securities. All future grants remain subject to board approval, definitive documentation, applicable tax and legal review, and the terms of any future financing.
A5: 1. LEGAL OWNERSHIP TODAY — DELAWARE PARENT
A6: Metric | B6: Value | C6: Unit / Ownership | D6: Legal status | E6: Details | F6: Source / Control
A7: Authorized common shares | B7: 10000000 | C7: shares | D7: Authorized | E7: Cognics Systems, Inc. authorized common stock. | F7: Corporate records
A8: Issued common shares | B8: 9000000 | C8: shares | D8: Issued | E8: All issued shares are restricted common stock. | F8: Executed Founder Restricted Stock Purchase Agreement
A9: Legal holder | B9: THMS / Thomas Manrique | C9: 0.9 | D9: Current legal ownership | E9: 100% of issued shares; no other current legal stockholders. | F9: Issued-share ledger
A10: Legal issued ownership | B10: 0.9 | C10: of issued shares | D10: Current / legal | E10: Calculated against 9,000,000 issued common shares. | F10: 9,000,000 ÷ 9,000,000
A11: Founder restricted common stock | B11: 9000000 | C11: shares | D11: Issued / restricted | E11: Subject to company repurchase rights over unvested shares. | F11: Executed founder RSA
A12: Founder vesting commencement | B12: =DATE(2026,2,1) -> 46054 | C12: date | D12: Binding / executed | E12: Four-year vesting with a 12-month cliff. | F12: Executed founder RSA
A13: Founder vesting terms | B13: 48 months | C13: 12-month cliff | D13: Binding / executed | E13: 12/48 vest on Feb 1, 2027; 1/48 monthly thereafter. | F13: Executed founder RSA
A14: Current fully diluted planning view | B14: 10000000 | C14: illustrative units | D14: Pro forma only | E14: THMS 90% / ESOP reserve 10%; no team grants or SAFE shares are issued. | F14: Planning denominator ≠ legal issued shares
A15: French operating subsidiary | B15: Future French SASU | C15: 1 | D15: Wholly owned by parent | E15: No founder, core-team or SAFE ownership is modeled at SASU level. | F15: Cognics Systems, Inc. remains financing vehicle and owner of core IP.
A16: 2. RESERVED AND UNISSUED INSTRUMENTS
A17: Instrument | B17: Reserved amount | C17: % of planning denominator | D17: Issued today? | E17: Status | F17: Notes
A18: ESOP reserve | B18: 1000000 | C18: =B18/$B$7 -> 0.1 | D18: No | E18: Reserved / unissued | F18: Separate 10% reserve for broader employees, advisors and future grants; not part of the core-team target pool.
A19: SAFE conversion reserve | B19: TBD at conversion | C19: =$D$39 -> 0.1 | D19: No | E19: Board-authorized reserve | F19: No SAFE shares currently issued. Conversion mechanics and resulting legal share count remain TBD; modeled only in the pro forma scenario.
A20: Reserved ≠ issued. The ESOP reserve and future SAFE conversion reserve do not constitute current legal ownership.
A22: 3. PLANNED CORE-TEAM ALLOCATION
A23: Holder / Pool | B23: Role | C23: Illustrative planning units | D23: Pre-SAFE normalized ownership | E23: Post-SAFE target % | F23: Legal status | G23: Mechanism / Notes
A24: THMS | B24: Founder | C24: 4000000 | D24: =E24/SUM($E$24:$E$29) -> 0.44444444 | E24: 0.4 | F24: Retained target; planning-only | G24: Founder retained target following planned reallocation; current legal ownership remains 100% of issued shares.
A25: JSPH | B25: AI / Robotics | C25: 1500000 | D25: =E25/SUM($E$24:$E$29) -> 0.16666667 | E25: 0.15 | F25: Illustrative / ungranted | G25: Planned founder reallocation / future restricted-stock grant; subject to board approval and individual RSA execution.
A26: DALI | B26: Maths Applied | C26: 500000 | D26: =E26/SUM($E$24:$E$29) -> 0.055555556 | E26: 0.05 | F26: Illustrative / ungranted | G26: Planned founder reallocation / future restricted-stock grant; subject to board approval and individual RSA execution.
A27: NADR | B27: Embedded Systems | C27: 1000000 | D27: =E27/SUM($E$24:$E$29) -> 0.11111111 | E27: 0.1 | F27: Illustrative / ungranted | G27: Planned founder reallocation / future restricted-stock grant; subject to board approval and individual RSA execution.
A28: NEXT (future key Hire) | B28: AI / Robotics | C28: 1000000 | D28: =E28/SUM($E$24:$E$29) -> 0.11111111 | E28: 0.1 | F28: Illustrative / ungranted | G28: Separate key-hire target; not part of the ESOP reserve. Future RSA or option terms remain unexecuted.
A29: ESOP | B29: Broader employees / advisors | C29: 1000000 | D29: =E29/SUM($E$24:$E$29) -> 0.11111111 | E29: 0.1 | F29: Reserved / unissued | G29: Separate company reserve; not a current grant or legal ownership.
A30: CORE-TEAM AGGREGATE | B30: JSPH + DALI + NADR + future key hire | C30: =SUM(C25:C28) -> 4000000 | D30: =SUM(D25:D28) -> 0.44444444 | E30: =SUM(E25:E28) -> 0.4 | F30: Illustrative / ungranted | G30: 40% aggregate post-SAFE target.
A31: TOTAL PRE-SAFE PLANNED HOLDERS | B31: Founder + core team + ESOP | C31: =SUM(C24:C29) -> 9000000 | D31: =SUM(D24:D29) -> 1 | E31: =SUM(E24:E29) -> 0.9 | F31: Planning reconciliation | G31: Pre-SAFE normalized ownership is 100%; stated post-SAFE targets occupy 90%, before the 10% SAFE scenario.
A32: The 10,000,000-unit denominator is an illustrative fully diluted planning convention, not a representation that planned core-team grants or SAFE securities have been legally issued.
A34: 4. PROPOSED SAFE DILUTION
A35: Tier | B35: Investment amount (USD) | C35: Post-money cap (USD) | D35: Implied FD ownership | E35: Status | F35: Terms / Source
A36: Tier 1 | B36: ='Assumptions & Funding'!C15 -> 200000 | C36: ='Assumptions & Funding'!E15 -> 6000000 | D36: =B36/C36 -> 0.033333333 | E36: Proposed / unclosed | F36: YC post-money SAFE · cap only · no discount · no MFN · no automatic pro-rata
A37: Tier 2 | B37: ='Assumptions & Funding'!C16 -> 250000 | C37: ='Assumptions & Funding'!E16 -> 7500000 | D37: =B37/C37 -> 0.033333333 | E37: Proposed / unclosed | F37: YC post-money SAFE · cap only · no discount · no MFN · no automatic pro-rata
A38: Tier 3 | B38: ='Assumptions & Funding'!C17 -> 300000 | C38: ='Assumptions & Funding'!E17 -> 9000000 | D38: =B38/C38 -> 0.033333333 | E38: Proposed / unclosed | F38: YC post-money SAFE · cap only · no discount · no MFN · no automatic pro-rata
A39: TOTAL PROPOSED SAFE | B39: =SUM(B36:B38) -> 750000 | D39: =SUM(D36:D38) -> 0.1 | E39: Board-approved up to $750K | F39: No SAFEs issued, signed, closed, funded or converted as of the current model date.
A40: SAFE conversion is assumed only in the pro forma post-SAFE scenario. Illustrative ownership is calculated as investment ÷ post-money valuation cap.
A42: 5. PRO FORMA POST-SAFE OWNERSHIP
A43: Owner group | B43: Illustrative planning units | C43: Post-SAFE ownership | D43: Status | E43: Notes
A44: Founder THMS | B44: 4000000 | C44: =B44/$B$48 -> 0.4 | D44: Illustrative post-SAFE | E44: Founder target; not current legal issued ownership.
...

Sheet Hiring & Compensation Plan
A1: MONTHLY COMP SCHEDULE (Core-team)
A2: Core-team comps : Compensation follows three progressive stages: TEST, PRE-VALIDATION and VETTED. Timing and amounts remain subject to milestone achievement.
A4: NAME | B4: Profile | C4: Start Month | D4: Metric | E4: M1 | F4: M2 | G4: M3 | H4: M4 | I4: M5 | J4: M6 | K4: M7 | L4: M8 | M4: M9 | N4: M10 | O4: M11 | P4: M12 | Q4: M13 | R4: M14 | S4: M15 | T4: M16 | U4: M17 | V4: M18 | W4: TOTAL 12M | X4: TOTAL 18M | Z4: AVANTAGE JEI
A5: THMS | B5: Founder | C5: M1 | D5: Net mensuel | E5: 2000 | F5: 3000 | G5: 3000 | H5: 3000 | I5: 3000 | J5: 3000 | K5: 3000 | L5: 3000 | M5: 3000 | N5: 3000 | O5: 3000 | P5: 3000 | Q5: 3000 | R5: 3000 | S5: 3000 | T5: 3000 | U5: 3000 | V5: 3000 | W5: =SUM(E5:P5) -> 35000 | X5: =SUM(E5:V5) -> 53000 | Z5: an 1 -> an 2
A6: THMS | B6: Founder | C6: M1 | D6: Brut mensuel | E6: 2597.4 | F6: 3896.1 | G6: 3896.1 | H6: 3896.1 | I6: 3896.1 | J6: 3896.1 | K6: 3896.1 | L6: 3896.1 | M6: 3896.1 | N6: 3896.1 | O6: 3896.1 | P6: 3896.1 | Q6: 3896.1 | R6: 3896.1 | S6: 3896.1 | T6: 3896.1 | U6: 3896.1 | V6: 3896.1 | W6: =SUM(E6:P6) -> 45454.5 | X6: =SUM(E6:V6) -> 68831.1
A7: THMS | B7: Founder | C7: M1 | D7: Chargé normal | E7: 1090.91 | F7: 1636.36 | G7: 1636.36 | H7: 1636.36 | I7: 1636.36 | J7: 1636.36 | K7: 1636.36 | L7: 1636.36 | M7: 1636.36 | N7: 1636.36 | O7: 1636.36 | P7: 1636.36 | Q7: 1636.36 | R7: 1636.36 | S7: 1636.36 | T7: 1636.36 | U7: 1636.36 | V7: 1636.36 | W7: =SUM(E7:P7) -> 19090.87 | X7: =SUM(E7:V7) -> 28909.03
A8: THMS | B8: Founder | C8: M1 | D8: Chargé JEI | E8: 763.64 | F8: 1145.45 | G8: 1145.45 | H8: 1145.45 | I8: 1145.45 | J8: 1145.45 | K8: 1145.45 | L8: 1145.45 | M8: 1145.45 | N8: 1145.45 | O8: 1145.45 | P8: 1145.45 | Q8: 1145.45 | R8: 1145.45 | S8: 1145.45 | T8: 1145.45 | U8: 1145.45 | V8: 1145.45 | W8: =SUM(H8:P8) -> 10309.05 | X8: =SUM(H8:V8) -> 17181.75
A9: THMS | B9: Founder | C9: M1 | D9: Total mensuel | E9: 3361.04 | F9: 5041.56 | G9: 5041.56 | H9: 5041.56 | I9: 5041.56 | J9: 5041.56 | K9: 5041.56 | L9: 5041.56 | M9: 5041.56 | N9: 5041.56 | O9: 5041.56 | P9: 5041.56 | Q9: 5041.56 | R9: 5041.56 | S9: 5041.56 | T9: 5041.56 | U9: 5041.56 | V9: 5041.56 | W9: =SUM(E9:P9) -> 58818.2 | X9: =SUM(E9:V9) -> 89067.56 | Z9: =X7-X8 -> 11727.28
A10: JSPH | B10: AI/Robotics eng | C10: M2 | D10: Net mensuel | F10: 2000 | G10: 3000 | H10: 3000 | I10: 4000 | J10: 4000 | K10: 4000 | L10: 4000 | M10: 4000 | N10: 4000 | O10: 4000 | P10: 4000 | Q10: 4000 | R10: 4000 | S10: 4000 | T10: 4000 | U10: 4000 | V10: 4000 | W10: =SUM(E10:P10) -> 40000 | X10: =SUM(E10:V10) -> 64000 | Z10: an 1 -> an 2
A11: JSPH | B11: AI/Robotics eng | C11: M2 | D11: Brut mensuel | E11: 0 | F11: 2597.4 | G11: 2597.4 | H11: 3896.1 | I11: 3896.1 | J11: 5194.81 | K11: 5194.81 | L11: 5194.81 | M11: 5194.81 | N11: 5194.81 | O11: 5194.81 | P11: 5194.81 | Q11: 5194.81 | R11: 5194.81 | S11: 5194.81 | T11: 5194.81 | U11: 5194.81 | V11: 5194.81 | W11: =SUM(E11:P11) -> 49350.67 | X11: =SUM(E11:V11) -> 80519.53
A12: JSPH | B12: AI/Robotics eng | C12: M2 | D12: Chargé normal | E12: 0 | F12: 1090.91 | G12: 1090.91 | H12: 1636.36 | I12: 1636.36 | J12: 2181.82 | K12: 2181.82 | L12: 2181.82 | M12: 2181.82 | N12: 2181.82 | O12: 2181.82 | P12: 2181.82 | Q12: 2181.82 | R12: 2181.82 | S12: 2181.82 | T12: 2181.82 | U12: 2181.82 | V12: 2181.82 | W12: =SUM(E12:P12) -> 20727.28 | X12: =SUM(E12:V12) -> 33818.2
A13: JSPH | B13: AI/Robotics eng | C13: M2 | D13: Chargé JEI | E13: 0 | F13: 763.64 | G13: 763.64 | H13: 1145.45 | I13: 1145.45 | J13: 1527.27 | K13: 1527.27 | L13: 1527.27 | M13: 1527.27 | N13: 1527.27 | O13: 1527.27 | P13: 1527.27 | Q13: 1527.27 | R13: 1527.27 | S13: 1527.27 | T13: 1527.27 | U13: 1527.27 | V13: 1527.27 | W13: =SUM(E13:P13) -> 14509.07 | X13: =SUM(E13:V13) -> 23672.69
A14: JSPH | B14: AI/Robotics eng | C14: M2 | D14: Total mensuel | E14: 0 | F14: 3361.04 | G14: 3361.04 | H14: 5041.56 | I14: 5041.56 | J14: 6722.08 | K14: 6722.08 | L14: 6722.08 | M14: 6722.08 | N14: 6722.08 | O14: 6722.08 | P14: 6722.08 | Q14: 6722.08 | R14: 6722.08 | S14: 6722.08 | T14: 6722.08 | U14: 6722.08 | V14: 6722.08 | W14: =SUM(E14:P14) -> 63859.76 | X14: =SUM(E14:V14) -> 104192.24 | Z14: =X12-X13 -> 10145.51
A15: DALI | B15: Maths applied eng | C15: M2 | D15: Net mensuel | E15: 0 | F15: 1000 | G15: 1000 | H15: 2000 | I15: 2000 | J15: 2500 | K15: 2500 | L15: 2500 | M15: 2500 | N15: 2500 | O15: 2500 | P15: 2500 | Q15: 2500 | R15: 2500 | S15: 2500 | T15: 2500 | U15: 2500 | V15: 2500 | W15: =SUM(E15:P15) -> 23500 | X15: =SUM(E15:V15) -> 38500 | Z15: an 1 -> an 2
A16: DALI | B16: Maths applied eng | C16: M2 | D16: Brut mensuel | E16: 0 | F16: 0 | G16: 0 | H16: 2597.4 | I16: 2597.4 | J16: 3246.75 | K16: 3246.75 | L16: 3246.75 | M16: 3246.75 | N16: 3246.75 | O16: 3246.75 | P16: 3246.75 | Q16: 3246.75 | R16: 3246.75 | S16: 3246.75 | T16: 3246.75 | U16: 3246.75 | V16: 3246.75 | W16: =SUM(E16:P16) -> 27922.05 | X16: =SUM(E16:V16) -> 47402.55
A17: DALI | B17: Maths applied eng | C17: M2 | D17: Chargé normal | E17: 0 | F17: 0 | G17: 0 | H17: 1090.91 | I17: 1090.91 | J17: 1363.64 | K17: 1363.64 | L17: 1363.64 | M17: 1363.64 | N17: 1363.64 | O17: 1363.64 | P17: 1363.64 | Q17: 1363.64 | R17: 1363.64 | S17: 1363.64 | T17: 1363.64 | U17: 1363.64 | V17: 1363.64 | W17: =SUM(E17:P17) -> 11727.3 | X17: =SUM(E17:V17) -> 19909.14
A18: DALI | B18: Maths applied eng | C18: M2 | D18: Chargé JEI | E18: 0 | F18: 0 | G18: 0 | H18: 763.64 | I18: 763.64 | J18: 954.55 | K18: 954.55 | L18: 954.55 | M18: 954.55 | N18: 954.55 | O18: 954.55 | P18: 954.55 | Q18: 954.55 | R18: 954.55 | S18: 954.55 | T18: 954.55 | U18: 954.55 | V18: 954.55 | W18: =SUM(E18:P18) -> 8209.13 | X18: =SUM(E18:V18) -> 13936.43
A19: DALI | B19: Maths applied eng | C19: M2 | D19: Total mensuel | E19: 0 | F19: 1212 | G19: 1212 | H19: 3361.04 | I19: 3361.04 | J19: 4201.3 | K19: 4201.3 | L19: 4201.3 | M19: 4201.3 | N19: 4201.3 | O19: 4201.3 | P19: 4201.3 | Q19: 4201.3 | R19: 4201.3 | S19: 4201.3 | T19: 4201.3 | U19: 4201.3 | V19: 4201.3 | W19: =SUM(E19:P19) -> 38555.18 | X19: =SUM(E19:V19) -> 63762.98 | Z19: =X17-X18 -> 5972.71
A20: NADR | B20: Embedded Sys eng | C20: M5 | D20: Net mensuel | E20: 0 | F20: 0 | G20: 0 | H20: 0 | I20: 2000 | J20: 2500 | K20: 2500 | L20: 3000 | M20: 3000 | N20: 3000 | O20: 3000 | P20: 3000 | Q20: 3000 | R20: 3000 | S20: 3000 | T20: 3000 | U20: 3000 | V20: 3000 | W20: =SUM(E20:P20) -> 22000 | X20: =SUM(E20:V20) -> 40000 | Z20: an 1 -> an 2
A21: NADR | B21: Embedded Sys eng | C21: M5 | D21: Brut mensuel | E21: 0 | F21: 0 | G21: 0 | H21: 0 | I21: 2597.4 | J21: 3246.75 | K21: 3246.75 | L21: 3896.1 | M21: 3896.1 | N21: 3896.1 | O21: 3896.1 | P21: 3896.1 | Q21: 3896.1 | R21: 3896.1 | S21: 3896.1 | T21: 3896.1 | U21: 3896.1 | V21: 3896.1 | W21: =SUM(E21:P21) -> 28571.4 | X21: =SUM(E21:V21) -> 51948
A22: NADR | B22: Embedded Sys eng | C22: M5 | D22: Chargé normal | E22: 0 | F22: 0 | G22: 0 | H22: 0 | I22: 1090.91 | J22: 1363.64 | K22: 1363.64 | L22: 1636.36 | M22: 1636.36 | N22: 1636.36 | O22: 1636.36 | P22: 1636.36 | Q22: 1636.36 | R22: 1636.36 | S22: 1636.36 | T22: 1636.36 | U22: 1636.36 | V22: 1636.36 | W22: =SUM(E22:P22) -> 11999.99 | X22: =SUM(E22:V22) -> 21818.15
A23: NADR | B23: Embedded Sys eng | C23: M5 | D23: Chargé JEI | E23: 0 | F23: 0 | G23: 0 | H23: 0 | I23: 763.64 | J23: 954.55 | K23: 954.55 | L23: 1145.45 | M23: 1145.45 | N23: 1145.45 | O23: 1145.45 | P23: 1145.45 | Q23: 1145.45 | R23: 1145.45 | S23: 1145.45 | T23: 1145.45 | U23: 1145.45 | V23: 1145.45 | W23: =SUM(E23:P23) -> 8399.99 | X23: =SUM(E23:V23) -> 15272.69 | Z23: =X21-X22 -> 30129.85
A24: NADR | B24: Embedded Sys eng | C24: M5 | D24: Total mensuel | E24: 0 | F24: 0 | G24: 0 | H24: 0 | I24: 3361.04 | J24: 4201.3 | K24: 4201.3 | L24: 5041.56 | M24: 5041.56 | N24: 5041.56 | O24: 5041.56 | P24: 5041.56 | Q24: 5041.56 | R24: 5041.56 | S24: 5041.56 | T24: 5041.56 | U24: 5041.56 | V24: 5041.56 | W24: =SUM(E24:P24) -> 36971.44 | X24: =SUM(E24:V24) -> 67220.8
A25: MAXM | B25: Fractional CTO (900/j) | C25: M2 | D25: Total (2,5j / m) | F25: 2250 | H25: 2250 | J25: 2250 | M25: 2250 | Q25: 2250 | U25: 2250 | W25: =SUM(E25:P25) -> 9000 | X25: =SUM(E25:V25) -> 13500
D27: Total mensuel | E27: =E9+E14+E19+E24+E25 -> 3361.04 | F27: =F9+F14+F19+F24+F25 -> 11864.6 | G27: =G9+G14+G19+G24+G25 -> 9614.6 | H27: =H9+H14+H19+H24+H25 -> 15694.16 | I27: =I9+I14+I19+I24+I25 -> 16805.2 | J27: =J9+J14+J19+J24+J25 -> 22416.24 | K27: =K9+K14+K19+K24+K25 -> 20166.24 | L27: =L9+L14+L19+L24+L25 -> 21006.5 | ... V27: =V9+V14+V19+V24+V25 -> 21006.5 | W27: =SUM(E27:P27) -> 207204.58 | X27: =SUM(E27:V27) -> 337743.58 | Z27: =Z23+Z19+Z14+Z9 -> 57975.35
A28: Hiring/Comp Budget = | B28: 350000 | E28: =B28-E27 -> 346638.96 | F28: =E28-F27 -> 334774.36 | G28: =F28-G27 -> 325159.76 | H28: =G28-H27 -> 309465.6 | I28: =H28-I27 -> 292660.4 | J28: =I28-J27 -> 270244.16 | K28: =J28-K27 -> 250077.92 | L28: =K28-L27 -> 229071.42 | M28: =L28-M27 -> 205814.92 | ... V28: =U28-V27 -> 12256.42 | W28: =P28 -> 142795.42 | X28: =V28+Z27 -> 70231.77
W29: Y1 Remainder | X29: M18 Remainder
A30: VESTING SCHEDULE (Core-team)
A31: Core-team vesting : 7-year progressive vesting starting from each person’s start date, with early cliff/low initial allocation and heavier vesting in years 4–7. Illustrative only : subject to final board approval, individual role, and counsel review at grant time.
E33: Y1 (vested) | F33: Left to vest | G33: Y2 (vested) | H33: Left to vest | I33: Y3 (vested) | J33: Left to vest | K33: Y4 (vested) | L33: Left to vest | M33: Y5 (vested) | N33: Left to vest | O33: Y6 (vested) | P33: Left to vest | Q33: Y7 (vested) | R33: Left to vest
A34: THMS | B34: Founder Equity | D34: % vested per year | E34: 0.25 | F34: 0.75 | G34: 0.5 | H34: 0.5 | I34: 0.75 | J34: 0.25 | K34: 1 | L34: 0 | M34: 1 | N34: 0 | O34: 1 | P34: 0 | Q34: 1 | R34: 0
B35: 40% (4,000,000 shares) | D35: total shares | E35: 1000000 | F35: 3000000 | G35: 2000000 | H35: 2000000 | I35: 3000000 | J35: 1000000 | K35: 4000000 | L35: 0 | M35: 4000000 | N35: 0 | O35: 4000000 | P35: 0 | Q35: 4000000 | R35: 0
A36: JSPH | B36: AI/Robotics Equity | D36: % vested per year | E36: CLIFF | F36: 1 | G36: 0.05 | H36: 0.95 | I36: 0.1 | J36: 0.85 | K36: 0.15 | L36: 0.7 | M36: 0.2 | N36: 0.5 | O36: 0.25 | P36: 0.25 | Q36: 0.25 | R36: 0
B37: 15% (1,500,000 shares) | D37: total shares | E37: 0 | F37: 1500000 | G37: 75000 | H37: 1425000 | I37: 225000 | J37: 1275000 | K37: 450000 | L37: 1050000 | M37: 750000 | N37: 750000 | O37: 1125000 | P37: 375000 | Q37: 1500000 | R37: 0
A38: DALI | B38: Maths applied Equity | D38: % vested per year | E38: CLIFF | F38: 1 | G38: 0.05 | H38: 0.95 | I38: 0.1 | J38: 0.85 | K38: 0.15 | L38: 0.7 | M38: 0.2 | N38: 0.5 | O38: 0.25 | P38: 0.25 | Q38: 0.25 | R38: 0
B39: 5% (500,000 shares) | D39: total shares | E39: 0 | F39: 500000 | G39: 25000 | H39: 475000 | I39: 75000 | J39: 425000 | K39: 150000 | L39: 350000 | M39: 250000 | N39: 250000 | O39: 375000 | P39: 125000 | Q39: 500000 | R39: 0
A40: NADR | B40: Embedded Sys Equity | D40: % vested per year | E40: CLIFF | F40: 1 | G40: 0.05 | H40: 0.95 | I40: 0.1 | J40: 0.85 | K40: 0.15 | L40: 0.7 | M40: 0.2 | N40: 0.5 | O40: 0.25 | P40: 0.25 | Q40: 0.25 | R40: 0
B41: 10% (1,000,000 shares) | D41: total shares | E41: 0 | F41: 1000000 | G41: 50000 | H41: 950000 | I41: 150000 | J41: 850000 | K41: 300000 | L41: 700000 | M41: 500000 | N41: 500000 | O41: 750000 | P41: 250000 | Q41: 1000000 | R41: 0
A42: NEXT | B42: Key-hire AI/Robotics | D42: To be found
B43: 10% (1,000,000 shares) | D43: provisioned
...

Sheet MVP & lab hardware BOM
A1: BILL OF MATERIALS : MVP & LAB
A3: CATEGORY | B3: ITEM | C3: Qty | D3: M1 | E3: M2 | F3: M3 | G3: M4 | H3: M5 | I3: M6 | J3: M7 | K3: M8 | L3: M9 | M3: M10 | N3: M11 | O3: M12 | P3: M13 | Q3: M14 | R3: M15 | S3: M16 | T3: M17 | U3: M18 | V3: TOTAL 12M | W3: TOTAL 18M | X3: COST TYPE | Y3: Unit Cost | Z3: Grade | AA3: Pricing Source | AB3: Purchase Month | AC3: Technical Milestone | AD3: Technical Purpose
A4: Capture Hardware
A5: Capture Hardware | B5: Xsens MVN Awinda full system | C5: 1 | D5: 7800 | V5: =SUM(D5:O5) -> 7800 | W5: =SUM(D5:U5) -> 7800 | X5: CapEx | Y5: 7800 | Z5: A | AA5: Vendor / market pricing | AB5: Month 1 | AC5: Capture stack deployment | AD5: Full-body IMMU suit for operator kinematics, posture and balance capture
A6: Capture Hardware | B6: Delsys Trigno Avanti Starter Kit | C6: 1 | D6: 5300 | V6: =SUM(D6:O6) -> 5300 | W6: =SUM(D6:U6) -> 5300 | X6: CapEx | Y6: 5300 | Z6: A | AA6: Vendor / market pricing | AB6: Month 1 | AC6: Biomechanics sensing setup | AD6: Wireless sEMG for muscle activation and torque proxy estimation
A7: Capture Hardware | B7: BNC sync cable | C7: 1 | D7: 20 | V7: =SUM(D7:O7) -> 20 | W7: =SUM(D7:U7) -> 20 | X7: CapEx | Y7: 20 | Z7: A | AA7: Commodity accessory pricing | AB7: Month 1 | AC7: Sensor synchronization | AD7: Hardware trigger alignment between Xsens and Delsys
A8: Capture Hardware | B8: MANUS Quantum Metagloves | C8: 1 | D8: 4999 | V8: =SUM(D8:O8) -> 4999 | W8: =SUM(D8:U8) -> 4999 | X8: CapEx | Y8: 4999 | Z8: B | AA8: Current reseller / market pricing | AB8: Month 1 | AC8: Hand tracking setup | AD8: Hand kinematics for manipulation, teleoperation and finger pose capture
A9: Capture Hardware | B9: OSMO tactile glove custom build | C9: 1 | D9: 3590 | V9: =SUM(D9:O9) -> 3590 | W9: =SUM(D9:U9) -> 3590 | X9: CapEx | Y9: 3590 | Z9: C | AA9: Engineering build estimate (materials ~1.090€ + labour 2.500€) | AB9: Month 1 | AC9: Tactile sensing prototype | AD9: Full palmar and finger contact, normal + shear force mapping
A10: Capture Hardware | B10: Intel RealSense D435i | C10: 1 | D10: 320 | V10: =SUM(D10:O10) -> 320 | W10: =SUM(D10:U10) -> 320 | X10: CapEx | Y10: 320 | Z10: B | AA10: Current street price (roboticscenter.ai depth camera survey) - Intel wound down RealSense unit, supply continuity risk | AB10: Month 1 | AC10: RGB-D scene capture | AD10: Close-range RGB-D capture of manipulation scenes
A11: Capture Hardware | B11: RoboSense RS-Helios-16P LiDAR | C11: 1 | G11: 1500 | V11: =SUM(D11:O11) -> 1500 | W11: =SUM(D11:U11) -> 1500 | X11: CapEx | Y11: 1500 | Z11: C | AA11: Reseller estimate - confirm with EU quote before data room | AB11: Month 4 | AC11: Room-scale spatial mapping | AD11: Room-scale 3D spatial mapping and larger workcell geometry
A12: Capture Hardware | B12: Logitech Brio 4K | C12: 1 | D12: 170 | V12: =SUM(D12:O12) -> 170 | W12: =SUM(D12:U12) -> 170 | X12: CapEx | Y12: 170 | Z12: A | AA12: Logitech FR store list price 169,99EUR | AB12: Month 1 | AC12: Visual annotation setup | AD12: Frontal RGB stream for annotation and VLM input
A13: Capture Hardware | B13: Rode NT-USB Mini | C13: 1 | D13: 100 | V13: =SUM(D13:O13) -> 100 | W13: =SUM(D13:U13) -> 100 | X13: CapEx | Y13: 100 | Z13: A | AA13: Public retail pricing | AB13: Month 1 | AC13: Voice annotation setup | AD13: Voice-to-text annotation during capture sessions
A14: Capture Hardware | B14: CVAT subscription (annual) | C14: 1 | D14: 290 | O14: 290 | V14: =SUM(D14:O14) -> 580 | W14: =SUM(D14:U14) -> 580 | X14: OpEx | Y14: 290 | Z14: B | AA14: Subscription pricing | AB14: Month 1 | AC14: Annotation workflow launch | AD14: Manual and assisted annotation interface
A15: Capture Hardware | B15: Network switch, cabling, UPS, accessories | C15: 1 | D15: 850 | V15: =SUM(D15:O15) -> 850 | W15: =SUM(D15:U15) -> 850 | X15: CapEx | Y15: 850 | Z15: B | AA15: System-integrator estimate | AB15: Month 1 | AC15: Lab infrastructure setup | AD15: Lab networking, power conditioning and cable management
A16: Capture Hardware | B16: Spare sensors, spare cables, calibration consumables | C16: 1 | D16: 650 | V16: =SUM(D16:O16) -> 650 | W16: =SUM(D16:U16) -> 650 | X16: OpEx | Y16: 650 | Z16: C | AA16: Engineering contingency | AB16: Month 1 | AC16: Capture continuity readiness | AD16: Reduce downtime and avoid blocked capture sessions
A17: Capture Hardware | B17: Multi-sensor calibration rig / jig | C17: 1 | D17: 1500 | V17: =SUM(D17:O17) -> 1500 | W17: =SUM(D17:U17) -> 1500 | X17: CapEx | Y17: 1500 | Z17: C | AA17: Engineering estimate | AB17: Month 1 | AC17: Multi-sensor calibration | AD17: Cross-sensor spatial and temporal alignment across Xsens, Delsys, MANUS, OSMO and RGB-D
B18: Capture Hardware — SUBTOTAL | D18: =SUM(D5:D17) -> 25589 | E18: =SUM(E5:E17) -> 0 | F18: =SUM(F5:F17) -> 0 | G18: =SUM(G5:G17) -> 1500 | H18: =SUM(H5:H17) -> 0 | I18: =SUM(I5:I17) -> 0 | J18: =SUM(J5:J17) -> 0 | K18: =SUM(K5:K17) -> 0 | ... W18: =SUM(W5:W17) -> 27379
A20: Shared Dataset Storage
A21: Shared Dataset Storage | B21: Synology NAS or equivalent | C21: 1 | D21: 900 | V21: =SUM(D21:O21) -> 900 | W21: =SUM(D21:U21) -> 900 | X21: CapEx | Y21: 900 | Z21: B | AA21: Market pricing | AB21: Month 1 | AC21: Dataset storage deployment | AD21: Shared proprietary dataset storage and collaboration
A22: Shared Dataset Storage | B22: RAID drives / redundancy | C22: 1 | D22: 300 | V22: =SUM(D22:O22) -> 300 | W22: =SUM(D22:U22) -> 300 | X22: CapEx | Y22: 300 | Z22: B | AA22: Market pricing | AB22: Month 1 | AC22: Redundancy & backup | AD22: Redundant storage for captured datasets and backups
A23: Shared Dataset Storage | B23: NAS setup / accessories | C23: 1 | D23: 100 | V23: =SUM(D23:O23) -> 100 | W23: =SUM(D23:U23) -> 100 | X23: CapEx | Y23: 100 | Z23: C | AA23: Engineering estimate | AB23: Month 1 | AC23: Storage commissioning | AD23: Cabling, trays and deployment accessories
B24: Shared Dataset Storage — SUBTOTAL | D24: =SUM(D21:D23) -> 1300 | E24: =SUM(E21:E23) -> 0 | F24: =SUM(F21:F23) -> 0 | G24: =SUM(G21:G23) -> 0 | H24: =SUM(H21:H23) -> 0 | I24: =SUM(I21:I23) -> 0 | J24: =SUM(J21:J23) -> 0 | K24: =SUM(K21:K23) -> 0 | ... W24: =SUM(W21:W23) -> 1300
A26: Development Compute
A27: Development Compute | B27: GPU: RTX 5090 class | C27: 1 | D27: 4000 | V27: =SUM(D27:O27) -> 4000 | W27: =SUM(D27:U27) -> 4000 | X27: CapEx | Y27: 4000 | Z27: B | AA27: French retail 3.700-5.500EUR (MSRP 2.349EUR not achievable) | AB27: Month 1 | AC27: Local AI workstation deployment | AD27: Local VLM inference, moderate experimentation, fast iteration
A28: Development Compute | B28: CPU: Ryzen 9 9950X / i9 class | C28: 1 | D28: 800 | V28: =SUM(D28:O28) -> 800 | W28: =SUM(D28:U28) -> 800 | X28: CapEx | Y28: 800 | Z28: B | AA28: Market estimate | AB28: Month 1 | AC28: Local AI workstation deployment | AD28: Dataset preprocessing, annotation orchestration, robotics development
A29: Development Compute | B29: Motherboard: X870E / Z890 class | C29: 1 | D29: 450 | V29: =SUM(D29:O29) -> 450 | W29: =SUM(D29:U29) -> 450 | X29: CapEx | Y29: 450 | Z29: B | AA29: Market estimate | AB29: Month 1 | AC29: Local AI workstation deployment | AD29: PCIe lanes, storage expansion, workstation reliability
A30: Development Compute | B30: RAM: 192 GB DDR5 | C30: 1 | D30: 1250 | V30: =SUM(D30:O30) -> 1250 | W30: =SUM(D30:U30) -> 1250 | X30: CapEx | Y30: 1250 | Z30: B | AA30: 2026 DDR5 shortage: 32GB kits 385-460EUR | AB30: Month 1 | AC30: Local AI workstation deployment | AD30: Large preprocessing jobs, local experiments, multi-process pipelines
A31: Development Compute | B31: NVMe SSD: 2 TB OS / workspace | C31: 1 | D31: 180 | V31: =SUM(D31:O31) -> 180 | W31: =SUM(D31:U31) -> 180 | X31: CapEx | Y31: 180 | Z31: A | AA31: Commodity pricing | AB31: Month 1 | AC31: Local AI workstation deployment | AD31: System drive and application workspace
A32: Development Compute | B32: NVMe SSD: 4 TB scratch / dataset staging | C32: 2 | D32: 700 | V32: =SUM(D32:O32) -> 700 | W32: =SUM(D32:U32) -> 700 | X32: CapEx | Y32: 350 | Z32: A | AA32: Commodity pricing | AB32: Month 1 | AC32: Local AI workstation deployment | AD32: Fast local scratch, cached models, staged datasets
A33: Development Compute | B33: HDD / SSD backup pool | C33: 1 | D33: 300 | V33: =SUM(D33:O33) -> 300 | W33: =SUM(D33:U33) -> 300 | X33: CapEx | Y33: 300 | Z33: B | AA33: Market estimate | AB33: Month 1 | AC33: Local AI workstation deployment | AD33: Secondary local backup and snapshot retention
A34: Development Compute | B34: PSU: 1200W Platinum | C34: 1 | D34: 300 | V34: =SUM(D34:O34) -> 300 | W34: =SUM(D34:U34) -> 300 | X34: CapEx | Y34: 300 | Z34: B | AA34: Market estimate | AB34: Month 1 | AC34: Local AI workstation deployment | AD34: Stable power delivery for high-end GPU workloads
A35: Development Compute | B35: Cooling: high-end air or 360 mm AIO | C35: 1 | D35: 250 | V35: =SUM(D35:O35) -> 250 | W35: =SUM(D35:U35) -> 250 | X35: CapEx | Y35: 250 | Z35: B | AA35: Market estimate | AB35: Month 1 | AC35: Local AI workstation deployment | AD35: Thermal headroom for sustained inference and preprocessing
A36: Development Compute | B36: Case / assembly / cabling | C36: 1 | D36: 250 | V36: =SUM(D36:O36) -> 250 | W36: =SUM(D36:U36) -> 250 | X36: CapEx | Y36: 250 | Z36: B | AA36: Market estimate | AB36: Month 1 | AC36: Local AI workstation deployment | AD36: Build integration and serviceability
A37: Development Compute | B37: UPS for workstation, 1500 VA line-interactive | C37: 1 | D37: 550 | V37: =SUM(D37:O37) -> 550 | W37: =SUM(D37:U37) -> 550 | X37: CapEx | Y37: 550 | Z37: B | AA37: Re-specified for 575W GPU + 170W CPU sustained load | AB37: Month 1 | AC37: Local AI workstation deployment | AD37: Prevent data loss and corruption during power events
A38: Development Compute | B38: Dual 27-inch monitors | C38: 2 | D38: 600 | V38: =SUM(D38:O38) -> 600 | W38: =SUM(D38:U38) -> 600 | X38: CapEx | Y38: 300 | Z38: B | AA38: Market estimate | AB38: Month 1 | AC38: Local AI workstation deployment | AD38: Annotation, debugging and simultaneous pipeline monitoring
A39: Development Compute | B39: Keyboard, mouse, webcam, headset, peripherals | C39: 1 | D39: 250 | V39: =SUM(D39:O39) -> 250 | W39: =SUM(D39:U39) -> 250 | X39: CapEx | Y39: 250 | Z39: A | AA39: Commodity pricing | AB39: Month 1 | AC39: Local AI workstation deployment | AD39: Daily development and annotation ergonomics
B40: Development Compute — SUBTOTAL | D40: =SUM(D27:D39) -> 9880 | E40: =SUM(E27:E39) -> 0 | F40: =SUM(F27:F39) -> 0 | G40: =SUM(G27:G39) -> 0 | H40: =SUM(H27:H39) -> 0 | I40: =SUM(I27:I39) -> 0 | J40: =SUM(J27:J39) -> 0 | K40: =SUM(K27:K39) -> 0 | ... W40: =SUM(W27:W39) -> 9880
A42: Embedded AI Compute
A43: Embedded AI Compute | B43: Jetson AGX Orin Developer Kit | C43: 1 | G43: 3499 | V43: =SUM(D43:O43) -> 3499 | W43: =SUM(D43:U43) -> 3499 | X43: CapEx | Y43: 3499 | Z43: A | AA43: Vendor / public pricing | AB43: Month 4 | AC43: Runtime validation (Orin) | AD43: Embedded deployment, runtime validation, ROS2 integration
A44: Embedded AI Compute | B44: Orin: NVMe SSD for edge logging | C44: 1 | G44: 150 | V44: =SUM(D44:O44) -> 150 | W44: =SUM(D44:U44) -> 150 | X44: CapEx | Y44: 150 | Z44: A | AA44: Commodity pricing | AB44: Month 4 | AC44: Runtime validation (Orin) | AD44: Local buffering of sensor logs and TrustVault artefacts
...

Sheet HQ & lab est.
A1: HQ & LAB OPERATING COST PLAN
A2: 18-month headquarters, lab occupancy and core-team hosting estimate. Monthly cash-planning view; assumptions and provisional items are identified in the notes.
A3: CATEGORY | B3: ITEM | C3: Qty | D3: M1 | E3: M2 | F3: M3 | G3: M4 | H3: M5 | I3: M6 | J3: M7 | K3: M8 | L3: M9 | M3: M10 | N3: M11 | O3: M12 | P3: M13 | Q3: M14 | R3: M15 | S3: M16 | T3: M17 | U3: M18 | V3: TOTAL 12M | W3: TOTAL 18M | X3: COST TYPE | Y3: BASIS | Z3: NOTES
A4: OCCUPANCY & LEASE
A5: Occupancy & Lease | B5: Rent | C5: 18 | D5: 5000 | E5: 5000 | F5: 5000 | G5: 5000 | H5: 5000 | I5: 5000 | J5: 5000 | K5: 5000 | L5: 5000 | M5: 5000 | N5: 5000 | O5: 5000 | P5: 5000 | Q5: 5000 | R5: 5000 | S5: 5000 | T5: 5000 | U5: 5000 | V5: =SUM(D5:O5) -> 60000 | W5: =SUM(D5:U5) -> 90000 | X5: OpEx | Y5: €5,000 / month | Z5: User-provided estimate; recurring from M1 to M18.
A6: Occupancy & Lease | B6: Premises / tenant liability insurance | C6: 18 | D6: 50 | E6: 50 | F6: 50 | G6: 50 | H6: 50 | I6: 50 | J6: 50 | K6: 50 | L6: 50 | M6: 50 | N6: 50 | O6: 50 | P6: 50 | Q6: 50 | R6: 50 | S6: 50 | T6: 50 | U6: 50 | V6: =SUM(D6:O6) -> 600 | W6: =SUM(D6:U6) -> 900 | X6: OpEx | Y6: €50 / month | Z6: User-provided estimate; separate from equipment insurance in the BOM.
A7: Occupancy & Lease | B7: Security deposit (recoverable) | C7: 1 | D7: 10000 | V7: =SUM(D7:O7) -> 10000 | W7: =SUM(D7:U7) -> 10000 | X7: Working Capital | Y7: 2 months of rent; paid M1 | Z7: Provisional assumption: €10,000. Cash requirement, not an operating expense.
A8: Occupancy & Lease | B8: Lease, agency, legal and move-in fees | C8: 1 | D8: 5000 | V8: =SUM(D8:O8) -> 5000 | W8: =SUM(D8:U8) -> 5000 | X8: OpEx | Y8: One-off provision; M1 | Z8: Provisional €5,000 pending property and lease terms.
B9: Occupancy & Lease — SUBTOTAL | D9: =SUM(D5:D8) -> 20050 | E9: =SUM(E5:E8) -> 5050 | F9: =SUM(F5:F8) -> 5050 | G9: =SUM(G5:G8) -> 5050 | H9: =SUM(H5:H8) -> 5050 | I9: =SUM(I5:I8) -> 5050 | J9: =SUM(J5:J8) -> 5050 | K9: =SUM(K5:K8) -> 5050 | ... W9: =SUM(W5:W8) -> 105900
A11: FACILITIES & UTILITIES
A12: Facilities & Utilities | B12: Electricity, heating and water | C12: 18 | D12: 100 | E12: 100 | F12: 100 | G12: 100 | H12: 100 | I12: 100 | J12: 100 | K12: 100 | L12: 100 | M12: 100 | N12: 100 | O12: 100 | P12: 100 | Q12: 100 | R12: 100 | S12: 100 | T12: 100 | U12: 100 | V12: =SUM(D12:O12) -> 1200 | W12: =SUM(D12:U12) -> 1800 | X12: OpEx | Y12: €100 / month | Z12: User-provided utility estimate; validate against property size and lab energy load.
A13: Facilities & Utilities | B13: Business internet / telecom | C13: 18 | D13: 100 | E13: 100 | F13: 100 | G13: 100 | H13: 100 | I13: 100 | J13: 100 | K13: 100 | L13: 100 | M13: 100 | N13: 100 | O13: 100 | P13: 100 | Q13: 100 | R13: 100 | S13: 100 | T13: 100 | U13: 100 | V13: =SUM(D13:O13) -> 1200 | W13: =SUM(D13:U13) -> 1800 | X13: OpEx | Y13: €100 / month | Z13: Provisional estimate added separately from utilities.
A14: Facilities & Utilities | B14: Cleaning and household supplies | C14: 18 | D14: 250 | E14: 250 | F14: 250 | G14: 250 | H14: 250 | I14: 250 | J14: 250 | K14: 250 | L14: 250 | M14: 250 | N14: 250 | O14: 250 | P14: 250 | Q14: 250 | R14: 250 | S14: 250 | T14: 250 | U14: 250 | V14: =SUM(D14:O14) -> 3000 | W14: =SUM(D14:U14) -> 4500 | X14: OpEx | Y14: €250 / month | Z14: Provisional estimate for shared living and work areas.
A15: Facilities & Utilities | B15: Minor maintenance and repairs | C15: 18 | D15: 150 | E15: 150 | F15: 150 | G15: 150 | H15: 150 | I15: 150 | J15: 150 | K15: 150 | L15: 150 | M15: 150 | N15: 150 | O15: 150 | P15: 150 | Q15: 150 | R15: 150 | S15: 150 | T15: 150 | U15: 150 | V15: =SUM(D15:O15) -> 1800 | W15: =SUM(D15:U15) -> 2700 | X15: OpEx | Y15: €150 / month | Z15: Provisional recurring maintenance reserve.
A16: Facilities & Utilities | B16: Furniture, fit-out and appliances | C16: 1 | D16: 5000 | V16: =SUM(D16:O16) -> 5000 | W16: =SUM(D16:U16) -> 5000 | X16: CapEx | Y16: €5,000 one-off; M1 | Z16: Validated provision: €5,000 for furniture, fit-out and appliances; paid in M1.
B17: Facilities & Utilities — SUBTOTAL | D17: =SUM(D12:D16) -> 5600 | E17: =SUM(E12:E16) -> 600 | F17: =SUM(F12:F16) -> 600 | G17: =SUM(G12:G16) -> 600 | H17: =SUM(H12:H16) -> 600 | I17: =SUM(I12:I16) -> 600 | J17: =SUM(J12:J16) -> 600 | K17: =SUM(K12:K16) -> 600 | ... W17: =SUM(W12:W16) -> 15800
A19: CORE-TEAM HOSTING
A20: Core-team Hosting | B20: Food and shared meals | D20: =250*((VALUE(SUBSTITUTE('Hiring & Compensation Plan'!$C$5,"M",""))<=VALUE(SUBSTITUTE(D$3,"M","")))+(VALUE(SUBSTITUTE('Hiring & Compensation Plan'!$C$10,"M",""))<=VALUE(SUBSTITUTE(D$3,"M","")))+(VALUE(SUBSTITUTE('Hiring & Compensation Plan'!$C$15,"M",""))<=VALUE(SUBSTITUTE(D$3,"M","")))+(VALUE(SUBSTITUTE('Hiring & Compensation Plan'!$C$20,"M",""))<=VALUE(SUBSTITUTE(D$3,"M","")))) -> 250 | E20: =250*((VALUE(SUBSTITUTE('Hiring & Compensation Plan'!$C$5,"M",""))<=VALUE(SUBSTITUTE(E$3,"M","")))+(VALUE(SUBSTITUTE('Hiring & Compensation Plan'!$C$10,"M",""))<=VALUE(SUBSTITUTE(E$3,"M","")))+(VALUE(SUBSTITUTE('Hiring & Compensation Plan'!$C$15,"M",""))<=VALUE(SUBSTITUTE(E$3,"M","")))+(VALUE(SUBSTITUTE('Hiring & Compensation Plan'!$C$20,"M",""))<=VALUE(SUBSTITUTE(E$3,"M","")))) -> 750 | F20: =250*((VALUE(SUBSTITUTE('Hiring & Compensation Plan'!$C$5,"M",""))<=VALUE(SUBSTITUTE(F$3,"M","")))+(VALUE(SUBSTITUTE('Hiring & Compensation Plan'!$C$10,"M",""))<=VALUE(SUBSTITUTE(F$3,"M","")))+(VALUE(SUBSTITUTE('Hiring & Compensation Plan'!$C$15,"M",""))<=VALUE(SUBSTITUTE(F$3,"M","")))+(VALUE(SUBSTITUTE('Hiring & Compensation Plan'!$C$20,"M",""))<=VALUE(SUBSTITUTE(F$3,"M","")))) -> 750 | G20: =250*((VALUE(SUBSTITUTE('Hiring & Compensation Plan'!$C$5,"M",""))<=VALUE(SUBSTITUTE(G$3,"M","")))+(VALUE(SUBSTITUTE('Hiring & Compensation Plan'!$C$10,"M",""))<=VALUE(SUBSTITUTE(G$3,"M","")))+(VALUE(SUBSTITUTE('Hiring & Compensation Plan'!$C$15,"M",""))<=VALUE(SUBSTITUTE(G$3,"M","")))+(VALUE(SUBSTITUTE('Hiring & Compensation Plan'!$C$20,"M",""))<=VALUE(SUBSTITUTE(G$3,"M","")))) -> 750 | H20: =250*((VALUE(SUBSTITUTE('Hiring & Compensation Plan'!$C$5,"M",""))<=VALUE(SUBSTITUTE(H$3,"M","")))+(VALUE(SUBSTITUTE('Hiring & Compensation Plan'!$C$10,"M",""))<=VALUE(SUBSTITUTE(H$3,"M","")))+(VALUE(SUBSTITUTE('Hiring & Compensation Plan'!$C$15,"M",""))<=VALUE(SUBSTITUTE(H$3,"M","")))+(VALUE(SUBSTITUTE('Hiring & Compensation Plan'!$C$20,"M",""))<=VALUE(SUBSTITUTE(H$3,"M","")))) -> 1000 | I20: =250*((VALUE(SUBSTITUTE('Hiring & Compensation Plan'!$C$5,"M",""))<=VALUE(SUBSTITUTE(I$3,"M","")))+(VALUE(SUBSTITUTE('Hiring & Compensation Plan'!$C$10,"M",""))<=VALUE(SUBSTITUTE(I$3,"M","")))+(VALUE(SUBSTITUTE('Hiring & Compensation Plan'!$C$15,"M",""))<=VALUE(SUBSTITUTE(I$3,"M","")))+(VALUE(SUBSTITUTE('Hiring & Compensation Plan'!$C$20,"M",""))<=VALUE(SUBSTITUTE(I$3,"M","")))) -> 1000 | J20: =250*((VALUE(SUBSTITUTE('Hiring & Compensation Plan'!$C$5,"M",""))<=VALUE(SUBSTITUTE(J$3,"M","")))+(VALUE(SUBSTITUTE('Hiring & Compensation Plan'!$C$10,"M",""))<=VALUE(SUBSTITUTE(J$3,"M","")))+(VALUE(SUBSTITUTE('Hiring & Compensation Plan'!$C$15,"M",""))<=VALUE(SUBSTITUTE(J$3,"M","")))+(VALUE(SUBSTITUTE('Hiring & Compensation Plan'!$C$20,"M",""))<=VALUE(SUBSTITUTE(J$3,"M","")))) -> 1000 | K20: =250*((VALUE(SUBSTITUTE('Hiring & Compensation Plan'!$C$5,"M",""))<=VALUE(SUBSTITUTE(K$3,"M","")))+(VALUE(SUBSTITUTE('Hiring & Compensation Plan'!$C$10,"M",""))<=VALUE(SUBSTITUTE(K$3,"M","")))+(VALUE(SUBSTITUTE('Hiring & Compensation Plan'!$C$15,"M",""))<=VALUE(SUBSTITUTE(K$3,"M","")))+(VALUE(SUBSTITUTE('Hiring & Compensation Plan'!$C$20,"M",""))<=VALUE(SUBSTITUTE(K$3,"M","")))) -> 1000 | ... U20: =250*((VALUE(SUBSTITUTE('Hiring & Compensation Plan'!$C$5,"M",""))<=VALUE(SUBSTITUTE(U$3,"M","")))+(VALUE(SUBSTITUTE('Hiring & Compensation Plan'!$C$10,"M",""))<=VALUE(SUBSTITUTE(U$3,"M","")))+(VALUE(SUBSTITUTE('Hiring & Compensation Plan'!$C$15,"M",""))<=VALUE(SUBSTITUTE(U$3,"M","")))+(VALUE(SUBSTITUTE('Hiring & Compensation Plan'!$C$20,"M",""))<=VALUE(SUBSTITUTE(U$3,"M","")))) -> 1000 | V20: =SUM(D20:O20) -> 10500 | W20: =SUM(D20:U20) -> 16500 | X20: OpEx | Y20: €250 / active core-team FTE / month | Z20: Linked to core-team Start Months in the Hiring & Compensation Plan.
B21: Core-team Hosting — SUBTOTAL | D21: =SUM(D20) -> 250 | E21: =SUM(E20) -> 750 | F21: =SUM(F20) -> 750 | G21: =SUM(G20) -> 750 | H21: =SUM(H20) -> 1000 | I21: =SUM(I20) -> 1000 | J21: =SUM(J20) -> 1000 | K21: =SUM(K20) -> 1000 | ... W21: =SUM(W20) -> 16500
A23: OPERATING CONSUMABLES
A24: Operating Consumables | B24: Office and lab consumables / miscellaneous | C24: 18 | D24: 250 | E24: 250 | F24: 250 | G24: 250 | H24: 250 | I24: 250 | J24: 250 | K24: 250 | L24: 250 | M24: 250 | N24: 250 | O24: 250 | P24: 250 | Q24: 250 | R24: 250 | S24: 250 | T24: 250 | U24: 250 | V24: =SUM(D24:O24) -> 3000 | W24: =SUM(D24:U24) -> 4500 | X24: OpEx | Y24: €250 / month | Z24: User-provided estimate; excludes technical hardware already budgeted in the BOM.
B25: Operating Consumables — SUBTOTAL | D25: =SUM(D24) -> 250 | E25: =SUM(E24) -> 250 | F25: =SUM(F24) -> 250 | G25: =SUM(G24) -> 250 | H25: =SUM(H24) -> 250 | I25: =SUM(I24) -> 250 | J25: =SUM(J24) -> 250 | K25: =SUM(K24) -> 250 | ... W25: =SUM(W24) -> 4500
A27: RISK PROVISION
A28: Risk Provision | B28: Operating contingency reserve | C28: 18 | D28: =5%*SUM(D5:D6,D12:D15,D20,D24) -> 307.5 | E28: =5%*SUM(E5:E6,E12:E15,E20,E24) -> 332.5 | F28: =5%*SUM(F5:F6,F12:F15,F20,F24) -> 332.5 | G28: =5%*SUM(G5:G6,G12:G15,G20,G24) -> 332.5 | H28: =5%*SUM(H5:H6,H12:H15,H20,H24) -> 345 | I28: =5%*SUM(I5:I6,I12:I15,I20,I24) -> 345 | J28: =5%*SUM(J5:J6,J12:J15,J20,J24) -> 345 | K28: =5%*SUM(K5:K6,K12:K15,K20,K24) -> 345 | ... U28: =5%*SUM(U5:U6,U12:U15,U20,U24) -> 345 | V28: =SUM(D28:O28) -> 4065 | W28: =SUM(D28:U28) -> 6135 | X28: Reserve | Y28: 5% of recurring HQ operating costs | Z28: Formula-driven; excludes deposit, entry fees and furniture/fit-out.
B29: Risk Provision — SUBTOTAL | D29: =SUM(D28) -> 307.5 | E29: =SUM(E28) -> 332.5 | F29: =SUM(F28) -> 332.5 | G29: =SUM(G28) -> 332.5 | H29: =SUM(H28) -> 345 | I29: =SUM(I28) -> 345 | J29: =SUM(J28) -> 345 | K29: =SUM(K28) -> 345 | ... W29: =SUM(W28) -> 6135
B31: TOTAL HQ & LAB — 18-MONTH CASH PLAN | D31: =D9+D17+D21+D25+D29 -> 26457.5 | E31: =E9+E17+E21+E25+E29 -> 6982.5 | F31: =F9+F17+F21+F25+F29 -> 6982.5 | G31: =G9+G17+G21+G25+G29 -> 6982.5 | H31: =H9+H17+H21+H25+H29 -> 7245 | I31: =I9+I17+I21+I25+I29 -> 7245 | J31: =J9+J17+J21+J25+J29 -> 7245 | K31: =K9+K17+K21+K25+K29 -> 7245 | ... W31: =W9+W17+W21+W25+W29 -> 148835
A34: EXECUTIVE SUMMARY | H34: NOTES & METHODOLOGY — HQ & LAB
A35: Category | B35: Total 12M | C35: Total 18M | D35: % of 18M total | E35: Cost behavior | F35: Scope
A36: OCCUPANCY & LEASE | B36: =V9 -> 75600 | C36: =W9 -> 105900 | D36: =C36/$W$31 -> 0.71152619 | E36: Recurring + M1 entry cash | F36: Rent, premises insurance, deposit and entry fees | H36: 1. User-provided assumptions retained unchanged: rent €5,000/month; premises insurance €50/month; utilities €100/month; office/lab miscellaneous €250/month; food €1,000/month at four active core-team FTE. 2. Food is modeled at €250 per active core-team FTE and linked to Start Month cells in the Hiring & Compensation Plan: 1 FTE in M1, 3 FTE in M2–M4 and 4 FTE from M5. 3. Security deposit is provisioned at two months of rent (€10,000), paid in M1 and treated as recoverable working capital rather than OpEx. 4. Lease, agency, legal and move-in fees are provisioned at €5,000 in M1 pending the selected property and lease structure. 5. Added provisional recurring estimates: internet €100/month; cleaning and household supplies €250/month; minor maintenance and repairs €150/month. 6. Furniture, fit-out and appliances are provisioned at €5,000 in M1 as upfront CapEx. 7. The €100/month utilities assumption is retained but should be validated against heating, water, property size and sustained lab-compute electricity consumption. 8. A 5% operating contingency is applied to recurring HQ costs only. It excludes the deposit, move-in fees and furniture/fit-out. 9. VAT treatment is not modeled in this tab. Values are cash-planning estimates and must later be normalized consistently across the financial model. 10. Excluded from this tab: Paris–Toulouse travel, payroll, business taxes/CFE, lab hardware already in the BOM, robot freight and broader corporate overhead.
A37: FACILITIES & UTILITIES | B37: =V17 -> 12200 | C37: =W17 -> 15800 | D37: =C37/$W$31 -> 0.10615783 | E37: Recurring + M1 fit-out | F37: Utilities, connectivity, cleaning, maintenance and fit-out
A38: CORE-TEAM HOSTING | B38: =V21 -> 10500 | C38: =W21 -> 16500 | D38: =C38/$W$31 -> 0.11086102 | E38: Scales with active FTE | F38: Food at €250 per active core-team FTE
A39: OPERATING CONSUMABLES | B39: =V25 -> 3000 | C39: =W25 -> 4500 | D39: =C39/$W$31 -> 0.030234824 | E39: Recurring | F39: Office and general lab consumables
A40: RISK PROVISION | B40: =V29 -> 4065 | C40: =W29 -> 6135 | D40: =C40/$W$31 -> 0.041220143 | E40: Formula-driven | F40: 5% contingency on recurring HQ operating costs
A41: GRAND TOTAL | B41: =SUM(B36:B40) -> 105365 | C41: =SUM(C36:C40) -> 148835 | D41: 1
A43: HQ & LAB KPIs
A44: Steady-state monthly HQ & lab cost | B44: =H31 -> 7245
A45: One-off entry cash requirements | B45: =W7+W8+W16 -> 20000
A46: Recoverable security deposit | B46: =W7 -> 10000
A47: 18M operating cost excl. recoverable deposit | B47: =W31-W7 -> 138835
A48: Food provision per active core-team FTE | B48: =250 -> 250

Sheet Other expenses
A1: STRATEGIC OPERATIONS, TRAVEL & PROFESSIONAL SERVICES
A2: 18-month operating budget for targeted expertise, partnership travel, core-team mobility, strategic hospitality and essential corporate services. No events or broad representation budget.
A3: CATEGORY | B3: ITEM | C3: Qty | D3: M1 | E3: M2 | F3: M3 | G3: M4 | H3: M5 | I3: M6 | J3: M7 | K3: M8 | L3: M9 | M3: M10 | N3: M11 | O3: M12 | P3: M13 | Q3: M14 | R3: M15 | S3: M16 | T3: M17 | U3: M18 | V3: TOTAL 12M | W3: TOTAL 18M | X3: COST TYPE | Y3: BASIS | Z3: NOTES
A4: ADVISORY & PROFESSIONAL SERVICES
A5: Advisory & Professional Services | B5: Robotics / embodied AI expert consultations | C5: 6 | E5: 1000 | G5: 1000 | I5: 1000 | K5: 2000 | N5: 2000 | Q5: 3000 | V5: =SUM(D5:O5) -> 7000 | W5: =SUM(D5:U5) -> 10000 | X5: OpEx | Y5: 6 targeted engagements; €10,000 total | Z5: User-defined envelope: 3 × €1,000, 2 × €2,000 and 1 × €3,000.
A6: Advisory & Professional Services | B6: Accounting, payroll and corporate administration | C6: 18 | D6: 500 | E6: 500 | F6: 500 | G6: 500 | H6: 500 | I6: 500 | J6: 500 | K6: 500 | L6: 500 | M6: 500 | N6: 500 | O6: 500 | P6: 500 | Q6: 500 | R6: 500 | S6: 500 | T6: 500 | U6: 500 | V6: =SUM(D6:O6) -> 6000 | W6: =SUM(D6:U6) -> 9000 | X6: OpEx | Y6: €500 / month | Z6: Provisional recurring support for bookkeeping, payroll administration, annual accounts and routine filings.
B7: Advisory & Professional Services — SUBTOTAL | D7: =SUM(D5:D6) -> 500 | E7: =SUM(E5:E6) -> 1500 | F7: =SUM(F5:F6) -> 500 | G7: =SUM(G5:G6) -> 1500 | H7: =SUM(H5:H6) -> 500 | I7: =SUM(I5:I6) -> 1500 | J7: =SUM(J5:J6) -> 500 | K7: =SUM(K5:K6) -> 2500 | ... W7: =SUM(W5:W6) -> 19000
A9: TRAVEL & PARTNERSHIP DEVELOPMENT
A10: Travel & Partnership Development | B10: Core-team Paris–Toulouse mobility | D10: =200*((VALUE(SUBSTITUTE('Hiring & Compensation Plan'!$C$10,"M",""))<=VALUE(SUBSTITUTE(D$3,"M","")))+(VALUE(SUBSTITUTE('Hiring & Compensation Plan'!$C$15,"M",""))<=VALUE(SUBSTITUTE(D$3,"M","")))+(VALUE(SUBSTITUTE('Hiring & Compensation Plan'!$C$20,"M",""))<=VALUE(SUBSTITUTE(D$3,"M","")))) -> 0 | E10: =200*((VALUE(SUBSTITUTE('Hiring & Compensation Plan'!$C$10,"M",""))<=VALUE(SUBSTITUTE(E$3,"M","")))+(VALUE(SUBSTITUTE('Hiring & Compensation Plan'!$C$15,"M",""))<=VALUE(SUBSTITUTE(E$3,"M","")))+(VALUE(SUBSTITUTE('Hiring & Compensation Plan'!$C$20,"M",""))<=VALUE(SUBSTITUTE(E$3,"M","")))) -> 400 | F10: =200*((VALUE(SUBSTITUTE('Hiring & Compensation Plan'!$C$10,"M",""))<=VALUE(SUBSTITUTE(F$3,"M","")))+(VALUE(SUBSTITUTE('Hiring & Compensation Plan'!$C$15,"M",""))<=VALUE(SUBSTITUTE(F$3,"M","")))+(VALUE(SUBSTITUTE('Hiring & Compensation Plan'!$C$20,"M",""))<=VALUE(SUBSTITUTE(F$3,"M","")))) -> 400 | G10: =200*((VALUE(SUBSTITUTE('Hiring & Compensation Plan'!$C$10,"M",""))<=VALUE(SUBSTITUTE(G$3,"M","")))+(VALUE(SUBSTITUTE('Hiring & Compensation Plan'!$C$15,"M",""))<=VALUE(SUBSTITUTE(G$3,"M","")))+(VALUE(SUBSTITUTE('Hiring & Compensation Plan'!$C$20,"M",""))<=VALUE(SUBSTITUTE(G$3,"M","")))) -> 400 | H10: =200*((VALUE(SUBSTITUTE('Hiring & Compensation Plan'!$C$10,"M",""))<=VALUE(SUBSTITUTE(H$3,"M","")))+(VALUE(SUBSTITUTE('Hiring & Compensation Plan'!$C$15,"M",""))<=VALUE(SUBSTITUTE(H$3,"M","")))+(VALUE(SUBSTITUTE('Hiring & Compensation Plan'!$C$20,"M",""))<=VALUE(SUBSTITUTE(H$3,"M","")))) -> 600 | I10: =200*((VALUE(SUBSTITUTE('Hiring & Compensation Plan'!$C$10,"M",""))<=VALUE(SUBSTITUTE(I$3,"M","")))+(VALUE(SUBSTITUTE('Hiring & Compensation Plan'!$C$15,"M",""))<=VALUE(SUBSTITUTE(I$3,"M","")))+(VALUE(SUBSTITUTE('Hiring & Compensation Plan'!$C$20,"M",""))<=VALUE(SUBSTITUTE(I$3,"M","")))) -> 600 | J10: =200*((VALUE(SUBSTITUTE('Hiring & Compensation Plan'!$C$10,"M",""))<=VALUE(SUBSTITUTE(J$3,"M","")))+(VALUE(SUBSTITUTE('Hiring & Compensation Plan'!$C$15,"M",""))<=VALUE(SUBSTITUTE(J$3,"M","")))+(VALUE(SUBSTITUTE('Hiring & Compensation Plan'!$C$20,"M",""))<=VALUE(SUBSTITUTE(J$3,"M","")))) -> 600 | K10: =200*((VALUE(SUBSTITUTE('Hiring & Compensation Plan'!$C$10,"M",""))<=VALUE(SUBSTITUTE(K$3,"M","")))+(VALUE(SUBSTITUTE('Hiring & Compensation Plan'!$C$15,"M",""))<=VALUE(SUBSTITUTE(K$3,"M","")))+(VALUE(SUBSTITUTE('Hiring & Compensation Plan'!$C$20,"M",""))<=VALUE(SUBSTITUTE(K$3,"M","")))) -> 600 | ... U10: =200*((VALUE(SUBSTITUTE('Hiring & Compensation Plan'!$C$10,"M",""))<=VALUE(SUBSTITUTE(U$3,"M","")))+(VALUE(SUBSTITUTE('Hiring & Compensation Plan'!$C$15,"M",""))<=VALUE(SUBSTITUTE(U$3,"M","")))+(VALUE(SUBSTITUTE('Hiring & Compensation Plan'!$C$20,"M",""))<=VALUE(SUBSTITUTE(U$3,"M","")))) -> 600 | V10: =SUM(D10:O10) -> 6000 | W10: =SUM(D10:U10) -> 9600 | X10: OpEx | Y10: €200 / active non-local member / month | Z10: Formula-linked to Joseph, Dali and Nader Start Months; assumes one necessary round trip per active member per month.
A11: Travel & Partnership Development | B11: International partnership missions | C11: 3 | I11: 3000 | N11: 3000 | S11: 3000 | V11: =SUM(D11:O11) -> 6000 | W11: =SUM(D11:U11) -> 9000 | X11: OpEx | Y11: 3 missions × €3,000 | Z11: Rare, targeted missions only; envelope includes transport, hotel, meals, local mobility and eSIM.
A12: Travel & Partnership Development | B12: Partner logistics, shipping and customs | C12: 3 | I12: 1500 | N12: 1500 | S12: 2000 | V12: =SUM(D12:O12) -> 3000 | W12: =SUM(D12:U12) -> 5000 | X12: OpEx | Y12: Event-driven provision | Z12: Provisional transport of samples, sensors or partner equipment; excludes robot purchase.
B13: Travel & Partnership Development — SUBTOTAL | D13: =SUM(D10:D12) -> 0 | E13: =SUM(E10:E12) -> 400 | F13: =SUM(F10:F12) -> 400 | G13: =SUM(G10:G12) -> 400 | H13: =SUM(H10:H12) -> 600 | I13: =SUM(I10:I12) -> 5100 | J13: =SUM(J10:J12) -> 600 | K13: =SUM(K10:K12) -> 600 | ... W13: =SUM(W10:W12) -> 23600
A15: STRATEGIC HOSPITALITY
A16: Strategic Hospitality | B16: Investor and key-profile working meals | C16: 16 | F16: 200 | G16: 200 | H16: 200 | I16: 200 | J16: 200 | K16: 200 | L16: 200 | M16: 200 | N16: 200 | O16: 200 | P16: 200 | Q16: 200 | R16: 200 | S16: 200 | T16: 200 | U16: 200 | V16: =SUM(D16:O16) -> 2000 | W16: =SUM(D16:U16) -> 3200 | X16: OpEx | Y16: €200 / month from M3 | Z16: Small controlled envelope for substantive investor, advisor and partner meetings.
B17: Strategic Hospitality — SUBTOTAL | D17: =SUM(D16) -> 0 | E17: =SUM(E16) -> 0 | F17: =SUM(F16) -> 200 | G17: =SUM(G16) -> 200 | H17: =SUM(H16) -> 200 | I17: =SUM(I16) -> 200 | J17: =SUM(J16) -> 200 | K17: =SUM(K16) -> 200 | ... W17: =SUM(W16) -> 3200
A19: CORPORATE SYSTEMS & ADMIN
A20: Corporate Systems & Admin | B20: General SaaS, collaboration and security tools | C20: 18 | D20: 250 | E20: 250 | F20: 250 | G20: 250 | H20: 250 | I20: 250 | J20: 250 | K20: 250 | L20: 250 | M20: 250 | N20: 250 | O20: 250 | P20: 250 | Q20: 250 | R20: 250 | S20: 250 | T20: 250 | U20: 250 | V20: =SUM(D20:O20) -> 3000 | W20: =SUM(D20:U20) -> 4500 | X20: OpEx | Y20: €250 / month | Z20: Provisional envelope for workspace, code collaboration, documentation, communication and account security; excludes BOM-specific tools.
A21: Corporate Systems & Admin | B21: Banking, payment and administrative fees | C21: 18 | D21: 100 | E21: 100 | F21: 100 | G21: 100 | H21: 100 | I21: 100 | J21: 100 | K21: 100 | L21: 100 | M21: 100 | N21: 100 | O21: 100 | P21: 100 | Q21: 100 | R21: 100 | S21: 100 | T21: 100 | U21: 100 | V21: =SUM(D21:O21) -> 1200 | W21: =SUM(D21:U21) -> 1800 | X21: OpEx | Y21: €100 / month | Z21: Provisional recurring corporate administration envelope.
B22: Corporate Systems & Admin — SUBTOTAL | D22: =SUM(D20:D21) -> 350 | E22: =SUM(E20:E21) -> 350 | F22: =SUM(F20:F21) -> 350 | G22: =SUM(G20:G21) -> 350 | H22: =SUM(H20:H21) -> 350 | I22: =SUM(I20:I21) -> 350 | J22: =SUM(J20:J21) -> 350 | K22: =SUM(K20:K21) -> 350 | ... W22: =SUM(W20:W21) -> 6300
A24: LEGAL, IP & RECRUITMENT
A25: Legal, IP & Recruitment | B25: Legal, partnership and investment documentation | C25: 4 | E25: 2000 | I25: 2000 | M25: 3000 | R25: 3000 | V25: =SUM(D25:O25) -> 7000 | W25: =SUM(D25:U25) -> 10000 | X25: OpEx | Y25: €10,000 staged provision | Z25: Contracts, partnership agreements, employment matters and financing documentation.
A26: Legal, IP & Recruitment | B26: IP strategy, patentability and freedom-to-operate work | C26: 2 | L26: 5000 | R26: 5000 | V26: =SUM(D26:O26) -> 5000 | W26: =SUM(D26:U26) -> 10000 | X26: OpEx | Y26: €10,000 staged provision | Z26: Initial IP landscaping and targeted specialist work; filing strategy remains scope-dependent.
A27: Legal, IP & Recruitment | B27: Recruitment, sourcing and technical assessment | C27: 1 | L27: 3000 | V27: =SUM(D27:O27) -> 3000 | W27: =SUM(D27:U27) -> 3000 | X27: OpEx | Y27: €3,000 event-driven | Z27: Small provision for a future specialist hire; excludes agency-scale recruitment.
A28: Legal, IP & Recruitment | B28: Corporate liability / cyber / D&O insurance | C28: 2 | D28: 2000 | P28: 2000 | V28: =SUM(D28:O28) -> 2000 | W28: =SUM(D28:U28) -> 4000 | X28: OpEx | Y28: €2,000 annual; M1 and M13 | Z28: Validated €4,000 cash provision covering corporate liability/RC Pro, cyber and D&O: €2,000 at M1 and renewal at M13; separate from premises and equipment insurance.
B29: Legal, IP & Recruitment — SUBTOTAL | D29: =SUM(D25:D28) -> 2000 | E29: =SUM(E25:E28) -> 2000 | F29: =SUM(F25:F28) -> 0 | G29: =SUM(G25:G28) -> 0 | H29: =SUM(H25:H28) -> 0 | I29: =SUM(I25:I28) -> 2000 | J29: =SUM(J25:J28) -> 0 | K29: =SUM(K25:K28) -> 0 | ... W29: =SUM(W25:W28) -> 27000
A31: RISK PROVISION
A32: Risk Provision | B32: Variable operations contingency | C32: 18 | D32: =10%*SUM(D5,D10:D12,D16,D25:D27) -> 0 | E32: =10%*SUM(E5,E10:E12,E16,E25:E27) -> 340 | F32: =10%*SUM(F5,F10:F12,F16,F25:F27) -> 60 | G32: =10%*SUM(G5,G10:G12,G16,G25:G27) -> 160 | H32: =10%*SUM(H5,H10:H12,H16,H25:H27) -> 80 | I32: =10%*SUM(I5,I10:I12,I16,I25:I27) -> 830 | J32: =10%*SUM(J5,J10:J12,J16,J25:J27) -> 80 | K32: =10%*SUM(K5,K10:K12,K16,K25:K27) -> 280 | ... U32: =10%*SUM(U5,U10:U12,U16,U25:U27) -> 80 | V32: =SUM(D32:O32) -> 3900 | W32: =SUM(D32:U32) -> 5980 | X32: Reserve | Y32: 10% of variable / event-driven costs | Z32: Applied to consulting, travel, hospitality, legal, IP, recruitment and partner logistics; excludes recurring accounting, SaaS and bank fees.
B33: Risk Provision — SUBTOTAL | D33: =SUM(D32) -> 0 | E33: =SUM(E32) -> 340 | F33: =SUM(F32) -> 60 | G33: =SUM(G32) -> 160 | H33: =SUM(H32) -> 80 | I33: =SUM(I32) -> 830 | J33: =SUM(J32) -> 80 | K33: =SUM(K32) -> 280 | ... W33: =SUM(W32) -> 5980
B35: TOTAL STRATEGIC OPERATIONS & TRAVEL — 18-MONTH PLAN | D35: =D7+D13+D17+D22+D29+D33 -> 2850 | E35: =E7+E13+E17+E22+E29+E33 -> 4590 | F35: =F7+F13+F17+F22+F29+F33 -> 1510 | G35: =G7+G13+G17+G22+G29+G33 -> 2610 | H35: =H7+H13+H17+H22+H29+H33 -> 1730 | I35: =I7+I13+I17+I22+I29+I33 -> 9980 | J35: =J7+J13+J17+J22+J29+J33 -> 1730 | K35: =K7+K13+K17+K22+K29+K33 -> 3930 | ... W35: =W7+W13+W17+W22+W29+W33 -> 85080
A38: EXECUTIVE SUMMARY | H38: NOTES & METHODOLOGY — STRATEGIC OPERATIONS
